Workbook
Name SpreadsheetBuilder_11: #REF!
Name SpreadsheetBuilder_5: #REF!
Name SpreadsheetBuilder_3: #REF!
Name SpreadsheetBuilder_7: #REF!
Name SpreadsheetBuilder_10: #REF!
Name SpreadsheetBuilder_9: #REF!
Name SpreadsheetBuilder_4: #REF!
Name SpreadsheetBuilder_8: #REF!
Name SpreadsheetBuilder_2: #REF!
Name SpreadsheetBuilder_1: #REF!
Name SpreadsheetBuilder_6: #REF!

Sheet Portada y Roles
A1: Taller 7: Construcción de un índice para entender cambios en la economía global antes y después del COVID.
A3: INTEGRANTES | B3: ROL | C3: APORTES CONCRETOS Y EVIDENCIA
A4: Sara Gabriela Rodríguez Moreno | B4: Especialista en visualización y comunicaciones. | C4: Diseño de los gráficos de los puntos (1.3, 2.3, 2.4, 2.5, 3.3), diseño de tablas de riesgos y gráficos de riesgos, recomendaciones finales, ver holas: Gráficas, Riesgos, Riesgos gráficas.
A5: Angélica María Díaz Niño | B5: Analista cuantitativo
A6: Juan Esteban Plazas Romero | B6: Líder del proyecto y enlace con el fondo.
A7: Danna Sofía Romero Ortíz | B7: Especialista en datos y reproducibilidad

Sheet S.FINANCIERO
A1: Start Date | B1: 42005 | D1: TOTAL VOLUME | E1: =$C$29+$E$29+$G$29+$I$29+$K$29+$M$29+$O$29+$Q$29+$S$29+$U$29 -> 827027719 | F1: Días hábiles enero | H1: =COUNTIFS(S.FINANCIERO!A7:A2876, ">="&DATE(2015,1,1), S.FINANCIERO!A7:A2876, "<="&DATE(2015,1,31)) -> 22
A2: End Date | B2: 46022 | D2: TOTAL PRICE | E2: =$B$29+$D$29+$F$29+$H$29+$J$29+$L$29+$N$29+$P$29+$R$29+$T$29 -> 10321.649
B4: RY CN Equity | D4: TD CN Equity | F4: BMO CN Equity | H4: BNS CN Equity | J4: CM CN Equity | L4: NA CN Equity | N4: BN CN Equity | P4: MFC CN Equity | R4: SLF CN Equity | T4: GWO CN Equity
B5: Last Price | C5: Volume | D5: Last Price | E5: Volume | F5: Last Price | G5: Volume | H5: Last Price | I5: Volume | J5: Last Price | K5: Volume | L5: Last Price | M5: Volume | N5: Last Price | O5: Volume | P5: Last Price | Q5: Volume | R5: Last Price | S5: Volume | T5: Last Price | U5: Volume
A6: Dates | B6: PX_LAST | C6: PX_VOLUME | D6: PX_LAST | E6: PX_VOLUME | F6: PX_LAST | G6: PX_VOLUME | H6: PX_LAST | I6: PX_VOLUME | J6: PX_LAST | K6: PX_VOLUME | L6: PX_LAST | M6: PX_VOLUME | N6: PX_LAST | O6: PX_VOLUME | P6: PX_LAST | Q6: PX_VOLUME | R6: PX_LAST | S6: PX_VOLUME | T6: PX_LAST | U6: PX_VOLUME
A7: 42005 | B7: 80.24 | C7: 1754082 | D7: 55.51 | E7: 3164204 | F7: 82.18 | G7: 1198340 | H7: 66.31 | I7: 2175178 | J7: 49.92 | K7: 1467646 | L7: 49.44 | M7: 1006708 | N7: 13.6263 | O7: 1975739 | P7: 22.18 | Q7: 2373177 | R7: 41.92 | S7: 826184 | T7: 33.59 | U7: 330101
A8: 42006 | B8: 80.7 | C8: 2053960 | D8: 55.22 | E8: 3381747 | F8: 82.55 | G8: 1535948 | H8: 65.54 | I8: 3104941 | J8: 50.18 | K8: 1761034 | L8: 50.05 | M8: 2492427 | N8: 13.851 | O8: 2212370 | P8: 22.24 | Q8: 2429216 | R8: 42.12 | S8: 1154335 | T8: 33.52 | U8: 463264
A9: 42009 | B9: 78.88 | C9: 4899383 | D9: 53.94 | E9: 6052935 | F9: 80.71 | G9: 2903830 | H9: 64.29 | I9: 4297801 | J9: 49.19 | K9: 3733264 | L9: 47.6 | M9: 3428782 | N9: 13.7176 | O9: 4405728 | P9: 21.65 | Q9: 5651467 | R9: 41.27 | S9: 1862689 | T9: 33.21 | U9: 843879
A10: 42010 | B10: 78.32 | C10: 4183934 | D10: 53.06 | E10: 7084123 | F10: 79.59 | G10: 2641256 | H10: 63.49 | I10: 4933820 | J10: 47.86 | K10: 5387808 | L10: 47.51 | M10: 2299252 | N10: 13.6403 | O10: 3244178 | P10: 21.12 | Q10: 5269957 | R10: 39.99 | S10: 2288364 | T10: 32.62 | U10: 884837
A11: 42011 | B11: 78.35 | C11: 3656208 | D11: 52.89 | E11: 6415429 | F11: 79.56 | G11: 2760621 | H11: 63.67 | I11: 5253386 | J11: 47.815 | K11: 4628744 | L11: 48.09 | M11: 1673238 | N11: 13.8744 | O11: 3802970 | P11: 21.26 | Q11: 4319715 | R11: 40.65 | S11: 2082615 | T11: 32.59 | U11: 558279
A12: 42012 | B12: 78.83 | C12: 3566051 | D12: 53.23 | E12: 4365671 | F12: 79.56 | G12: 2512251 | H12: 64.18 | I12: 3886694 | J12: 47.6 | K12: 5444720 | L12: 48.65 | M12: 2489164 | N12: 14.2793 | O12: 3701275 | P12: 21.68 | Q12: 3972116 | R12: 40.8 | S12: 1528686 | T12: 32.7 | U12: 1356490
A13: 42013 | B13: 77.48 | C13: 4030974 | D13: 52.58 | E13: 6012434 | F13: 78.27 | G13: 2479400 | H13: 63.01 | I13: 5200288 | J13: 46.92 | K13: 5928544 | L13: 47.33 | M13: 3488294 | N13: 14.2418 | O13: 4408631 | P13: 21.33 | Q13: 4243960 | R13: 40.18 | S13: 1161878 | T13: 32.7 | U13: 715255
A14: 42016 | B14: 76.81 | C14: 4419365 | D14: 52.06 | E14: 6632018 | F14: 77.52 | G14: 2642419 | H14: 61.96 | I14: 6330047 | J14: 46.545 | K14: 5049742 | L14: 45.84 | M14: 2904775 | N14: 14.3495 | O14: 3732713 | P14: 21.33 | Q14: 4225341 | R14: 40.05 | S14: 1606079 | T14: 32.4 | U14: 865721
A15: 42017 | B15: 76.7 | C15: 4249313 | D15: 51.97 | E15: 7481430 | F15: 76.33 | G15: 4173123 | H15: 61.92 | I15: 5519884 | J15: 46.88 | K15: 5468376 | L15: 45.86 | M15: 2321015 | N15: 14.6772 | O15: 4294380 | P15: 21.18 | Q15: 5440453 | R15: 39.97 | S15: 1497872 | T15: 32.53 | U15: 716295
A16: 42018 | B16: 75.68 | C16: 6066373 | D16: 50.54 | E16: 13670931 | F16: 75.31 | G16: 3430516 | H16: 61.65 | I16: 6105150 | J16: 46.025 | K16: 6008340 | L16: 45.02 | M16: 3271812 | N16: 14.5133 | O16: 4515028 | P16: 20.35 | Q16: 8150410 | R16: 38.06 | S16: 3009428 | T16: 31.83 | U16: 1157668
A17: 42019 | B17: 75.12 | C17: 4798586 | D17: 49.905 | E17: 8859765 | F17: 75.22 | G17: 3160463 | H17: 61.34 | I17: 4947461 | J17: 45.745 | K17: 5307358 | L17: 44.9 | M17: 2164148 | N17: 14.4244 | O17: 3481043 | P17: 19.89 | Q17: 8755512 | R17: 37.41 | S17: 3555698 | T17: 31.31 | U17: 899584
A18: 42020 | B18: 75.51 | C18: 5384800 | D18: 50.21 | E18: 7862636 | F18: 75.68 | G18: 2384208 | H18: 61.62 | I18: 5035350 | J18: 45.29 | K18: 4952642 | L18: 44.66 | M18: 2530699 | N18: 14.4548 | O18: 2513980 | P18: 20.23 | Q18: 6016491 | R18: 37.47 | S18: 2393982 | T18: 31.48 | U18: 953444
... A28: 42034 | B28: 71.74 | C28: 7833080 | D28: 50.6 | E28: 8118790 | F28: 73 | G28: 5206640 | H28: 61.06 | I28: 6673948 | J28: 44.09 | K28: 8467592 | L28: 44.21 | M28: 3410985 | N28: 15.1546 | O28: 5987183 | P28: 20.27 | Q28: 5804921 | R28: 38.86 | S28: 2398253 | T28: 32.21 | U28: 831534
A29: TOTALES | B29: =SUM(B7:B28) -> 1680.82 | C29: =SUM(C7:C28) -> 104170026 | D29: =SUM(D7:D28) -> 1145.395 | E29: =SUM(E7:E28) -> 143524894 | F29: =SUM(F7:F28) -> 1709.66 | G29: =SUM(G7:G28) -> 57960579 | H29: =SUM(H7:H28) -> 1385.46 | I29: =SUM(I7:I28) -> 96906118 | ... U29: =SUM(U7:U28) -> 18135111
A30: 42037 | B30: 72.91 | C30: 4722472 | D30: 51.32 | E30: 6366294 | F30: 74.18 | G30: 3363075 | H30: 62.05 | I30: 4102415 | J30: 44.675 | K30: 3661542 | L30: 45.02 | M30: 2343760 | N30: 15.3208 | O30: 4511741 | P30: 20.5 | Q30: 8948749 | R30: 40.37 | S30: 4592330 | T30: 32.6 | U30: 635399
A31: 42038 | B31: 74.83 | C31: 6235149 | D31: 52.79 | E31: 7283879 | F31: 75.95 | G31: 3182167 | H31: 63.84 | I31: 4514135 | J31: 45.795 | K31: 5418390 | L31: 46.82 | M31: 3682582 | N31: 15.1055 | O31: 5743157 | P31: 21.11 | Q31: 9374532 | R31: 41.35 | S31: 3474510 | T31: 33.19 | U31: 1481119
A32: 42039 | B32: 74.13 | C32: 3822865 | D32: 52.55 | E32: 4274212 | F32: 75.29 | G32: 2014635 | H32: 63.43 | I32: 3002111 | J32: 45.67 | K32: 4292116 | L32: 46.45 | M32: 2783604 | N32: 15.1616 | O32: 6117670 | P32: 21.4 | Q32: 9852920 | R32: 41.35 | S32: 2883700 | T32: 32.9 | U32: 1099029
A33: 42040 | B33: 75.44 | C33: 5463642 | D33: 53.66 | E33: 6731811 | F33: 76.91 | G33: 2628407 | H33: 64.56 | I33: 2886834 | J33: 46.44 | K33: 4736572 | L33: 46.97 | M33: 2834597 | N33: 15.3723 | O33: 3889745 | P33: 21.36 | Q33: 7452085 | R33: 40.87 | S33: 2716755 | T33: 33.04 | U33: 890681
A34: 42041 | B34: 76.07 | C34: 5498165 | D34: 54.23 | E34: 6101325 | F34: 77.75 | G34: 2679783 | H34: 65.13 | I34: 4061607 | J34: 46.77 | K34: 4562124 | L34: 47.8 | M34: 2594860 | N34: 15.3208 | O34: 2996730 | P34: 21.77 | Q34: 6231829 | R34: 41.28 | S34: 2172704 | T34: 33.62 | U34: 838452
A35: 42044 | B35: 76.4 | C35: 4108533 | D35: 54.52 | E35: 6063218 | F35: 77.92 | G35: 1983874 | H35: 65.47 | I35: 2553338 | J35: 46.91 | K35: 4523762 | L35: 47.73 | M35: 1027795 | N35: 15.157 | O35: 2521436 | P35: 21.92 | Q35: 17880330 | R35: 41.64 | S35: 1832528 | T35: 33.77 | U35: 535976
A36: 42045 | B36: 76.42 | C36: 3729242 | D36: 54.56 | E36: 3874754 | F36: 77.81 | G36: 1518492 | H36: 65.5 | I36: 2755773 | J36: 46.685 | K36: 2804828 | L36: 46.85 | M36: 1740404 | N36: 15.4472 | O36: 4446468 | P36: 21.72 | Q36: 7608578 | R36: 42.15 | S36: 2009318 | T36: 33.99 | U36: 726960
A37: 42046 | B37: 76.73 | C37: 2959490 | D37: 55 | E37: 4466389 | F37: 77.75 | G37: 2812411 | H37: 65.87 | I37: 3112362 | J37: 46.84 | K37: 3042668 | L37: 46.62 | M37: 2447535 | N37: 15.6297 | O37: 3523730 | P37: 21.84 | Q37: 5572935 | R37: 41.96 | S37: 2766697 | T37: 34.02 | U37: 750059
A38: 42047 | B38: 77.42 | C38: 4496953 | D38: 55.49 | E38: 6579829 | F38: 78.5 | G38: 2005788 | H38: 66.52 | I38: 4000466 | J38: 47.2 | K38: 3283566 | L38: 47.65 | M38: 1891331 | N38: 15.6578 | O38: 4210988 | P38: 21.34 | Q38: 16939906 | R38: 39.23 | S38: 9270095 | T38: 35.23 | U38: 2191518
A39: 42048 | B39: 77.56 | C39: 4047563 | D39: 55.5 | E39: 4595619 | F39: 78.69 | G39: 2059983 | H39: 67.2 | I39: 3461446 | J39: 47.45 | K39: 4064016 | L39: 47.71 | M39: 1347224 | N39: 15.8708 | O39: 3917234 | P39: 21.56 | Q39: 6696847 | R39: 38.98 | S39: 4706017 | T39: 35.87 | U39: 1772007
A40: 42051 | B40: 77.56 | C40: 4047563 | D40: 55.5 | E40: 4595619 | F40: 78.69 | G40: 2059983 | H40: 67.2 | I40: 3461446 | J40: 47.45 | K40: 4064016 | L40: 47.71 | M40: 1347224 | N40: 15.8708 | O40: 3917234 | P40: 21.56 | Q40: 6696847 | R40: 38.98 | S40: 4706017 | T40: 35.87 | U40: 1772007
A41: 42052 | B41: 77.7 | C41: 3322557 | D41: 55.58 | E41: 5086498 | F41: 78.97 | G41: 2023372 | H41: 67.37 | I41: 3486551 | J41: 47.695 | K41: 3218222 | L41: 47.95 | M41: 1217357 | N41: 15.9059 | O41: 4809837 | P41: 21.95 | Q41: 10227220 | R41: 39.26 | S41: 4929548 | T41: 36.83 | U41: 1648372
... A2877: 46022 | B2877: 233.99 | C2877: 2370151 | D2877: 129.36 | E2877: 3609002 | F2877: 178.25 | G2877: 1409660 | H2877: 101.23 | I2877: 5062753 | J2877: 124.43 | K2877: 2577509 | L2877: 172.61 | M2877: 1474399 | N2877: 63.02 | O2877: 2405975 | P2877: 49.95 | Q2877: 3068219 | R2877: 85.68 | S2877: 1688389 | T2877: 67.69 | U2877: 795287

Sheet S. MATERIALES
A1: Start Date | B1: 42005 | D1: T.VOLUME | E1: =SUM($C$29+$E$29+$G$29+$I$29+$K$29+$M$29+$O$29+$Q$29+$S$29+U29) -> 851883409
A2: End Date | B2: 46022 | D2: Días hábiles enero: | F2: =COUNTIFS(S.FINANCIERO!A7:A2876, ">="&DATE(2015,1,1), S.FINANCIERO!A7:A2876, "<="&DATE(2015,1,31)) -> 22
B4: ABX CN Equity | D4: AEM CN Equity | F4: LUG CN Equity | H4: WPM CN Equity | J4: FNV CN Equity | L4: TECK/B CN Equity | N4: K CN Equity | P4: FM CN Equity | R4: LUN CN Equity | T4: PAAS CN Equity
B5: Last Price | C5: Volume | D5: Last Price | E5: Volume | F5: Last Price | G5: Volume | H5: Last Price | I5: Volume | J5: Last Price | K5: Volume | L5: Last Price | M5: Volume | N5: Last Price | O5: Volume | P5: Last Price | Q5: Volume | R5: Last Price | S5: Volume | T5: Last Price | U5: Volume
A6: Dates | B6: PX_LAST | C6: PX_VOLUME | D6: PX_LAST | E6: PX_VOLUME | F6: PX_LAST | G6: PX_VOLUME | H6: PX_LAST | I6: PX_VOLUME | J6: PX_LAST | K6: PX_VOLUME | L6: PX_LAST | M6: PX_VOLUME | N6: PX_LAST | O6: PX_VOLUME | P6: PX_LAST | Q6: PX_VOLUME | R6: PX_LAST | S6: PX_VOLUME | T6: PX_LAST | U6: PX_VOLUME
A7: 42005 | B7: 12.52 | C7: 3498327 | D7: 28.92 | E7: 847249 | F7: 3.9518 | G7: 15850 | H7: 23.63 | I7: 1287495 | J7: 57.21 | K7: 398976 | L7: 15.88 | M7: 2390561 | N7: 3.26 | O7: 2665571 | P7: 16.51 | Q7: 2276589 | R7: 5.72 | S7: 2828823 | T7: 10.72 | U7: 421046
A8: 42006 | B8: 12.86 | C8: 5265356 | D8: 31.72 | E8: 2082146 | F8: 3.8855 | G8: 22210 | H8: 24.53 | I8: 1860059 | J8: 57.75 | K8: 647022 | L8: 16.13 | M8: 3043522 | N8: 3.42 | O8: 3879303 | P8: 17.29 | Q8: 2211468 | R8: 5.83 | S8: 2496801 | T8: 11.26 | U8: 624048
A9: 42009 | B9: 12.81 | C9: 5148425 | D9: 32.2 | E9: 2905673 | F9: 3.8191 | G9: 23600 | H9: 24.82 | I9: 2244611 | J9: 60.78 | K9: 987311 | L9: 15.57 | M9: 5426833 | N9: 3.48 | O9: 3992192 | P9: 15.85 | Q9: 3291694 | R9: 5.59 | S9: 3415431 | T9: 11.61 | U9: 760979
A10: 42010 | B10: 13.31 | C10: 7176405 | D10: 34.17 | E10: 3974471 | F10: 3.9423 | G10: 221384 | H10: 25.81 | I10: 2459597 | J10: 62.06 | K10: 1401541 | L10: 15.58 | M10: 3733142 | N10: 3.95 | O10: 11651171 | P10: 16.27 | Q10: 2841598 | R10: 5.57 | S10: 5100931 | T10: 12.1 | U10: 1150730
A11: 42011 | B11: 13.15 | C11: 5534475 | D11: 33.69 | E11: 2447008 | F11: 3.9802 | G11: 23715 | H11: 25.26 | I11: 2352338 | J11: 60.86 | K11: 1039549 | L11: 15.56 | M11: 3036783 | N11: 3.83 | O11: 4759953 | P11: 16.13 | Q11: 2274088 | R11: 5.45 | S11: 6690843 | T11: 11.94 | U11: 803725
A12: 42012 | B12: 12.79 | C12: 5440029 | D12: 33.13 | E12: 2146210 | F12: 3.9329 | G12: 85200 | H12: 24.96 | I12: 2189274 | J12: 59.79 | K12: 732389 | L12: 16.27 | M12: 4561990 | N12: 3.85 | O12: 6538609 | P12: 17.18 | Q12: 3073381 | R12: 5.42 | S12: 5224891 | T12: 11.72 | U12: 562397
A13: 42013 | B13: 13.04 | C13: 8157292 | D13: 35.29 | E13: 1735287 | F13: 3.8855 | G13: 38909 | H13: 25.77 | I13: 2268393 | J13: 61.74 | K13: 983008 | L13: 16.15 | M13: 3178282 | N13: 4.09 | O13: 6631096 | P13: 16.91 | Q13: 2054361 | R13: 5.47 | S13: 10035022 | T13: 12.2 | U13: 586490
A14: 42016 | B14: 13.58 | C14: 6570848 | D14: 37 | E14: 2269006 | F14: 3.857 | G14: 34316 | H14: 27.24 | I14: 3373423 | J14: 64.79 | K14: 1423962 | L14: 15.59 | M14: 5616973 | N14: 4.14 | O14: 6630046 | P14: 15.82 | Q14: 4514673 | R14: 5.16 | S14: 20433474 | T14: 12.8 | U14: 924348
A15: 42017 | B15: 12.76 | C15: 6307037 | D15: 35.55 | E15: 2332642 | F15: 3.7244 | G15: 27870 | H15: 26.88 | I15: 3175866 | J15: 61.6 | K15: 1260831 | L15: 14.66 | M15: 7647108 | N15: 3.81 | O15: 5823383 | P15: 13.47 | Q15: 9617955 | R15: 4.68 | S15: 14909401 | T15: 12.45 | U15: 708433
A16: 42018 | B16: 12.41 | C16: 8175975 | D16: 35.1 | E16: 2628583 | F16: 3.5348 | G16: 54100 | H16: 26.69 | I16: 3233149 | J16: 60.34 | K16: 982465 | L16: 13.7 | M16: 7779024 | N16: 3.8 | O16: 5409213 | P16: 11.7 | Q16: 15749882 | R16: 4.18 | S16: 35750004 | T16: 12.31 | U16: 842205
A17: 42019 | B17: 13.6 | C17: 11030584 | D17: 37.55 | E17: 2872244 | F17: 3.6486 | G17: 3000 | H17: 27.28 | I17: 4293124 | J17: 64.02 | K17: 1997322 | L17: 13.57 | M17: 6487795 | N17: 4.22 | O17: 12448700 | P17: 11.95 | Q17: 8331710 | R17: 4.14 | S17: 9080800 | T17: 12.81 | U17: 737575
A18: 42020 | B18: 14.09 | C18: 10784557 | D18: 39.06 | E18: 3004809 | F18: 3.6959 | G18: 41000 | H18: 27.92 | I18: 3143711 | J18: 65.96 | K18: 1366333 | L18: 14.2 | M18: 4920918 | N18: 4.29 | O18: 11155970 | P18: 13.28 | Q18: 6936369 | R18: 4.44 | S18: 10363640 | T18: 13.15 | U18: 997722
... A28: 42034 | B28: 16.25 | C28: 5976210 | D28: 42.84 | E28: 1746024 | F28: 3.8002 | G28: 146940 | H28: 29.19 | I28: 2361548 | J28: 73.33 | K28: 1669784 | L28: 16.45 | M28: 6354129 | N28: 4.31 | O28: 6878609 | P28: 11.55 | Q28: 7233187 | R28: 4.52 | S28: 7016414 | T28: 14.88 | U28: 2464030
A29: TOTALES | B29: =SUM(B6:B28) -> 312.88 | C29: =SUM(C7:C28) -> 148340985 | D29: =SUM(D7:D28) -> 823.21 | E29: =SUM(E7:E28) -> 48956069 | F29: =SUM(F7:F28) -> 83.6561 | G29: =SUM(G7:G28) -> 1418303 | H29: =SUM(H7:H28) -> 599.61 | I29: =SUM(I7:I28) -> 55932787 | J29: =SUM(J7:J28) -> 1432.32 | ... U29: =SUM(U7:U28) -> 18022571
A30: 42037 | B30: 16.21 | C30: 4081656 | D30: 43.48 | E30: 1287853 | F30: 3.8665 | G30: 9981 | H30: 29.1 | I30: 1850181 | J30: 73.04 | K30: 927654 | L30: 17.1 | M30: 4798703 | N30: 4.28 | O30: 5795357 | P30: 12.28 | Q30: 4040592 | R30: 4.69 | S30: 3423974 | T30: 14.86 | U30: 433249
A31: 42038 | B31: 15.7 | C31: 40497143 | D31: 41.86 | E31: 1705635 | F31: 3.8476 | G31: 1600 | H31: 28.02 | I31: 1967540 | J31: 69.61 | K31: 1315869 | L31: 18.37 | M31: 6742685 | N31: 4.08 | O31: 7087387 | P31: 13.12 | Q31: 6102918 | R31: 5.12 | S31: 11745499 | T31: 14.32 | U31: 535386
A32: 42039 | B32: 16.22 | C32: 4805028 | D32: 42.85 | E32: 1508373 | F32: 3.8476 | G32: 109010 | H32: 29.04 | I32: 1619448 | J32: 72.24 | K32: 936891 | L32: 17.98 | M32: 4332839 | N32: 4.21 | O32: 4105130 | P32: 12.7 | Q32: 4394108 | R32: 4.94 | S32: 6931741 | T32: 14.87 | U32: 474284
A33: 42040 | B33: 16.24 | C33: 4525444 | D33: 42.84 | E33: 1346587 | F33: 3.8476 | G33: 109010 | H33: 29.02 | I33: 1467823 | J33: 71.28 | K33: 852882 | L33: 18.56 | M33: 3832162 | N33: 4.28 | O33: 3655008 | P33: 12.96 | Q33: 4127185 | R33: 5.17 | S33: 5557715 | T33: 14.81 | U33: 317588
A34: 42041 | B34: 15.44 | C34: 5209548 | D34: 39.54 | E34: 2649150 | F34: 3.8476 | G34: 19300 | H34: 27.96 | I34: 2111612 | J34: 67.68 | K34: 900773 | L34: 18.07 | M34: 3376832 | N34: 4.06 | O34: 5031695 | P34: 13.03 | Q34: 3437957 | R34: 5.17 | S34: 7800517 | T34: 14.35 | U34: 525758
A35: 42044 | B35: 15.56 | C35: 3732396 | D35: 39.97 | E35: 1593774 | F35: 3.8002 | G35: 29400 | H35: 28.05 | I35: 1003547 | J35: 67.86 | K35: 679384 | L35: 18.62 | M35: 2719572 | N35: 4.14 | O35: 2674623 | P35: 12.83 | Q35: 2941527 | R35: 5.11 | S35: 3067372 | T35: 14.52 | U35: 337228
A36: 42045 | B36: 15.3 | C36: 5110290 | D36: 39.48 | E36: 1335374 | F36: 3.7907 | G36: 34000 | H36: 27.87 | I36: 1359974 | J36: 65.84 | K36: 1025611 | L36: 17.79 | M36: 4903628 | N36: 4.05 | O36: 4460526 | P36: 12.44 | Q36: 3756489 | R36: 4.89 | S36: 5868127 | T36: 14.43 | U36: 290168
A37: 42046 | B37: 15.1 | C37: 3941536 | D37: 38.9 | E37: 1305622 | F37: 3.7907 | G37: 112700 | H37: 27.88 | I37: 1484863 | J37: 65.25 | K37: 783823 | L37: 17.61 | M37: 5715387 | N37: 3.78 | O37: 8316288 | P37: 12.46 | Q37: 3524200 | R37: 4.83 | S37: 5047518 | T37: 14.46 | U37: 350279
A38: 42047 | B38: 15.15 | C38: 3621814 | D38: 40.65 | E38: 1992176 | F38: 3.8381 | G38: 14900 | H38: 28.02 | I38: 1746861 | J38: 65.27 | K38: 738733 | L38: 18.66 | M38: 5476976 | N38: 3.73 | O38: 6753668 | P38: 13.29 | Q38: 5789102 | R38: 5.02 | S38: 6077538 | T38: 14.58 | U38: 470529
A39: 42048 | B39: 15.12 | C39: 2795304 | D39: 40.66 | E39: 1246440 | F39: 3.7433 | G39: 10300 | H39: 28.35 | I39: 1085756 | J39: 65.07 | K39: 636789 | L39: 19.15 | M39: 5446049 | N39: 3.51 | O39: 13289996 | P39: 13.69 | Q39: 4715115 | R39: 5.34 | S39: 8537271 | T39: 14.78 | U39: 358057
A40: 42051 | B40: 15.12 | C40: 2795304 | D40: 40.66 | E40: 1246440 | F40: 3.7433 | G40: 10300 | H40: 28.35 | I40: 1085756 | J40: 65.07 | K40: 636789 | L40: 19.15 | M40: 5446049 | N40: 3.51 | O40: 13289996 | P40: 13.69 | Q40: 4715115 | R40: 5.34 | S40: 8537271 | T40: 14.78 | U40: 358057
A41: 42052 | B41: 14.83 | C41: 4818210 | D41: 38.69 | E41: 1445311 | F41: 3.5633 | G41: 13965 | H41: 26.89 | I41: 2248845 | J41: 61.88 | K41: 1388250 | L41: 19.52 | M41: 5412513 | N41: 3.34 | O41: 9861531 | P41: 13.83 | Q41: 4642722 | R41: 5.35 | S41: 5608697 | T41: 13.93 | U41: 418459
... A2877: 46022 | B2877: 59.79 | C2877: 3970632 | D2877: 232.76 | E2877: 1158075 | F2877: 108.054 | G2877: 300265 | H2877: 161.36 | I2877: 590227 | J2877: 284.51 | K2877: 328281 | L2877: 65.8 | M2877: 847036 | N2877: 38.66 | O2877: 3259742 | P2877: 36.8 | Q2877: 1861840 | R2877: 29.5 | S2877: 1273707 | T2877: 71.16 | U2877: 819713

Sheet S. ENERGÍA
A1: Start Date | B1: 42005 | D1: T.VOLUMEN | E1: =SUM($C$29+$E$29+$G$29+$I$29+$K$29+$M$29+$O$29+$Q$29+$S$29+$U$29) -> 863684714
A2: End Date | B2: 46022 | D2: Días hábiles enero | F2: =COUNTIFS(S.FINANCIERO!A7:A2876, ">="&DATE(2015,1,1), S.FINANCIERO!A7:A2876, "<="&DATE(2015,1,31)) -> 22
B4: SU CN Equity | D4: CNQ CN Equity | F4: ENB CN Equity | H4: TRP CN Equity | J4: CVE CN Equity | L4: IMO CN Equity | N4: PPL CN Equity | P4: TOU CN Equity | R4: WCP CN Equity | T4: ARX CN Equity
B5: Last Price | C5: Volume | D5: Last Price | E5: Volume | F5: Last Price | G5: Volume | H5: Last Price | I5: Volume | J5: Last Price | K5: Volume | L5: Last Price | M5: Volume | N5: Last Price | O5: Volume | P5: Last Price | Q5: Volume | R5: Last Price | S5: Volume | T5: Last Price | U5: Volume
A6: Dates | B6: PX_LAST | C6: PX_VOLUME | D6: PX_LAST | E6: PX_VOLUME | F6: PX_LAST | G6: PX_VOLUME | H6: PX_LAST | I6: PX_VOLUME | J6: PX_LAST | K6: PX_VOLUME | L6: PX_LAST | M6: PX_VOLUME | N6: PX_LAST | O6: PX_VOLUME | P6: PX_LAST | Q6: PX_VOLUME | R6: PX_LAST | S6: PX_VOLUME | T6: PX_LAST | U6: PX_VOLUME
A7: 42005 | B7: 36.9 | C7: 3037054 | D7: 17.7261 | E7: 5403978 | F7: 59.74 | G7: 1237038 | H7: 52.0168 | I7: 1398850 | J7: 23.97 | K7: 2294275 | L7: 50.05 | M7: 731860 | N7: 42.34 | O7: 872085 | P7: 38.7 | Q7: 761903 | R7: 11.44 | S7: 1535752 | T7: 25.16 | U7: 688919
A8: 42006 | B8: 37.35 | C8: 3483704 | D8: 17.9087 | E8: 5518772 | F8: 60.45 | G8: 1217710 | H8: 52.8549 | I8: 999992 | J8: 24.38 | K8: 2189665 | L8: 50.18 | M8: 869594 | N8: 43.35 | O8: 783083 | P8: 39.94 | Q8: 433186 | R8: 11.68 | S8: 1779673 | T8: 25.75 | U8: 855600
A9: 42009 | B9: 35.72 | C9: 8357137 | D9: 16.6799 | E9: 14521212 | F9: 58.11 | G9: 2644697 | H9: 50.8599 | I9: 2448962 | J9: 23.1 | K9: 4195159 | L9: 48 | M9: 1632277 | N9: 41.15 | O9: 1790889 | P9: 37.74 | Q9: 1343082 | R9: 10.53 | S9: 4559978 | T9: 23.71 | U9: 1368187
A10: 42010 | B10: 35.23 | C10: 8012673 | D10: 16.1963 | E10: 21719334 | F10: 56.01 | G10: 2932070 | H10: 49.3841 | I10: 2838913 | J10: 23.12 | K10: 5418766 | L10: 47.23 | M10: 1225444 | N10: 40.21 | O10: 2602478 | P10: 36.61 | Q10: 1512773 | R10: 10.33 | S10: 5112785 | T10: 23.39 | U10: 1548533
A11: 42011 | B11: 35.28 | C11: 6658542 | D11: 15.8804 | E11: 15421906 | F11: 55.52 | G11: 2546389 | H11: 49.1017 | I11: 2270360 | J11: 22.92 | K11: 4262246 | L11: 47.39 | M11: 942005 | N11: 39.55 | O11: 1677265 | P11: 37.22 | Q11: 886683 | R11: 10.38 | S11: 3539802 | T11: 23.34 | U11: 1284979
A12: 42012 | B12: 35.98 | C12: 6715235 | D12: 16.3344 | E12: 13473120 | F12: 56.14 | G12: 3132372 | H12: 50.04 | I12: 3530301 | J12: 23.52 | K12: 4686421 | L12: 48.11 | M12: 890777 | N12: 40.39 | O12: 1853076 | P12: 37.31 | Q12: 790050 | R12: 10.61 | S12: 5100007 | T12: 22.3 | U12: 8573063
A13: 42013 | B13: 35.59 | C13: 6830022 | D13: 16.369 | E13: 37700136 | F13: 55.35 | G13: 2774094 | H13: 50.4135 | I13: 3262279 | J13: 23.75 | K13: 3006416 | L13: 47.88 | M13: 849848 | N13: 39.8 | O13: 1405682 | P13: 37.56 | Q13: 580401 | R13: 10.6 | S13: 3864978 | T13: 22.14 | U13: 4084137
A14: 42016 | B14: 34.32 | C14: 6079920 | D14: 15.6978 | E14: 13827230 | F14: 54.63 | G14: 2406590 | H14: 48.7464 | I14: 2974967 | J14: 23.01 | K14: 3116521 | L14: 45.34 | M14: 1458693 | N14: 38.82 | O14: 1815654 | P14: 35.78 | Q14: 834834 | R14: 9.8 | S14: 4954893 | T14: 20.96 | U14: 2702096
A15: 42017 | B15: 34.81 | C15: 8456724 | D15: 15.762 | E15: 14497572 | F15: 53.47 | G15: 2941468 | H15: 47.8263 | I15: 3163897 | J15: 22.75 | K15: 3590159 | L15: 44.86 | M15: 2002029 | N15: 37.23 | O15: 2675389 | P15: 35.94 | Q15: 847852 | R15: 10 | S15: 4478649 | T15: 21.81 | U15: 2529358
A16: 42018 | B16: 34.87 | C16: 7735649 | D16: 16.1815 | E16: 15728822 | F16: 53.87 | G16: 2348146 | H16: 47.9083 | I16: 3730322 | J16: 23.32 | K16: 3565867 | L16: 45.19 | M16: 1959876 | N16: 38.19 | O16: 2191953 | P16: 37.06 | Q16: 1223972 | R16: 10.32 | S16: 6276055 | T16: 22.4 | U16: 2354308
A17: 42019 | B17: 34.22 | C17: 7162456 | D17: 16.1124 | E17: 17150146 | F17: 53.9 | G17: 1771442 | H17: 47.2706 | I17: 2917825 | J17: 23.07 | K17: 6410104 | L17: 44.94 | M17: 1327814 | N17: 37.26 | O17: 1676821 | P17: 37.59 | Q17: 977683 | R17: 10.25 | S17: 5357811 | T17: 21.93 | U17: 1797240
A18: 42020 | B18: 36 | C18: 6503901 | D18: 17.5237 | E18: 19795174 | F18: 56.55 | G18: 3159154 | H18: 48.3456 | I18: 2290580 | J18: 24.64 | K18: 4093987 | L18: 47.43 | M18: 1700218 | N18: 38.09 | O18: 1791940 | P18: 38.15 | Q18: 1247941 | R18: 11.12 | S18: 6369366 | T18: 22.18 | U18: 3286937
... A28: 42034 | B28: 37.89 | C28: 7905121 | D28: 18.1455 | E28: 10995712 | F28: 61.55 | G28: 2648268 | H28: 51.5067 | I28: 2483975 | J28: 24.09 | K28: 5542775 | L28: 47.24 | M28: 1455782 | N28: 39.48 | O28: 1678700 | P28: 34.94 | Q28: 1237213 | R28: 12.41 | S28: 9249048 | T28: 23 | U28: 1664152
A29: TOTAL | B29: =SUM(B6:B28) -> 793.44 | C29: =SUM(C7:C28) -> 140029286 | D29: =SUM(D7:D28) -> 374.5077 | E29: =SUM(E7:E28) -> 292376262 | F29: =SUM(F7:F28) -> 1279.74 | G29: =SUM(G7:G28) -> 52043203 | H29: =SUM(H7:H28) -> 1096.1703 | I29: =SUM(I7:I28) -> 56143944 | J29: =SUM(J7:J28) -> 520.595 | ... U29: =SUM(U7:U28) -> 48136025
A30: 42037 | B30: 39.35 | C30: 7478982 | D30: 19.2509 | E30: 13110464 | F30: 62.57 | G30: 7182970 | H30: 52.3084 | I30: 1868509 | J30: 25.09 | K30: 4790727 | L30: 49.35 | M30: 2105031 | N30: 40.66 | O30: 996348 | P30: 36.01 | Q30: 757793 | R30: 12.94 | S30: 5066618 | T30: 23.93 | U30: 1946507
A31: 42038 | B31: 39.55 | C31: 12233117 | D31: 19.5322 | E31: 21076226 | F31: 63.07 | G31: 2572761 | H31: 53.4471 | I31: 3151997 | J31: 25.6 | K31: 6400640 | L31: 50.7 | M31: 2154305 | N31: 41.44 | O31: 1484179 | P31: 38.51 | Q31: 1381423 | R31: 13.17 | S31: 8707368 | T31: 24.27 | U31: 4036391
A32: 42039 | B32: 37.49 | C32: 9000845 | D32: 18.5946 | E32: 12114094 | F32: 62.78 | G32: 2029407 | H32: 53.3469 | I32: 2037931 | J32: 25.04 | K32: 4818195 | L32: 49.56 | M32: 1941748 | N32: 39.72 | O32: 2329587 | P32: 38.3 | Q32: 1469360 | R32: 12.6 | S32: 7099277 | T32: 23.33 | U32: 2383631
A33: 42040 | B33: 38.55 | C33: 8642748 | D33: 19.2164 | E33: 10132226 | F33: 63.11 | G33: 2372591 | H33: 53.4835 | I33: 2098596 | J33: 25.4 | K33: 4518623 | L33: 50.8 | M33: 1233914 | N33: 39.82 | O33: 2151533 | P33: 38.84 | Q33: 937817 | R33: 13.27 | S33: 5894397 | T33: 23.49 | U33: 2510575
A34: 42041 | B34: 38.74 | C34: 6186611 | D34: 19.3348 | E34: 7621510 | F34: 61.24 | G34: 2250578 | H34: 52.691 | I34: 1885983 | J34: 25.59 | K34: 4033492 | L34: 50.8 | M34: 834078 | N34: 38.69 | O34: 1518792 | P34: 38.03 | Q34: 1019147 | R34: 13.43 | S34: 4690231 | T34: 23.48 | U34: 2069568
A35: 42044 | B35: 39.3 | C35: 4681130 | D35: 19.478 | E35: 8213124 | F35: 60.79 | G35: 1907910 | H35: 52.363 | I35: 1542796 | J35: 25.49 | K35: 2963370 | L35: 50.28 | M35: 1997670 | N35: 38.58 | O35: 1054140 | P35: 39.82 | Q35: 1035364 | R35: 13.65 | S35: 3293646 | T35: 24.19 | U35: 1858683
A36: 42045 | B36: 38.58 | C36: 5799113 | D36: 19.0634 | E36: 9332204 | F36: 61.22 | G36: 2074742 | H36: 52.8732 | I36: 1606719 | J36: 25.1 | K36: 3299100 | L36: 49.68 | M36: 1213192 | N36: 38.3 | O36: 2084638 | P36: 39.76 | Q36: 1610584 | R36: 13.08 | S36: 4107979 | T36: 23.92 | U36: 1419067
A37: 42046 | B37: 38.49 | C37: 4332636 | D37: 19.2115 | E37: 7103140 | F37: 61.54 | G37: 2426582 | H37: 53.1373 | I37: 1699989 | J37: 24.68 | K37: 2970621 | L37: 49.74 | M37: 1382733 | N37: 38.97 | O37: 2463038 | P37: 40 | Q37: 826789 | R37: 13.31 | S37: 3336120 | T37: 24.02 | U37: 1145282
A38: 42047 | B38: 39.12 | C38: 5329336 | D38: 19.2164 | E38: 8111822 | F38: 61.98 | G38: 2199111 | H38: 53.2922 | I38: 2229257 | J38: 24.63 | K38: 4268352 | L38: 50.83 | M38: 1116941 | N38: 40.16 | O38: 1878978 | P38: 40.58 | Q38: 745611 | R38: 13.69 | S38: 4189197 | T38: 24.99 | U38: 2842984
A39: 42048 | B39: 39.4 | C39: 4499800 | D39: 19.4434 | E39: 6295854 | F39: 61.52 | G39: 1104664 | H39: 52.1353 | I39: 2803213 | J39: 24.18 | K39: 4531701 | L39: 51.23 | M39: 1044275 | N39: 40.39 | O39: 1350638 | P39: 40.61 | Q39: 379030 | R39: 13.8 | S39: 3151135 | T39: 25.06 | U39: 2371903
A40: 42051 | B40: 39.4 | C40: 4499800 | D40: 19.4434 | E40: 6295854 | F40: 61.52 | G40: 1104664 | H40: 52.1353 | I40: 2803213 | J40: 24.18 | K40: 4531701 | L40: 51.23 | M40: 1044275 | N40: 40.39 | O40: 1350638 | P40: 40.61 | Q40: 379030 | R40: 13.8 | S40: 3151135 | T40: 25.06 | U40: 2371903
A41: 42052 | B41: 39.15 | C41: 5542827 | D41: 19.5174 | E41: 9207844 | F41: 61.79 | G41: 1226153 | H41: 51.9257 | I41: 2262977 | J41: 23.25 | K41: 5492430 | L41: 50.78 | M41: 1246050 | N41: 40.54 | O41: 1347694 | P41: 41.1 | Q41: 853222 | R41: 13.86 | S41: 3456798 | T41: 24.84 | U41: 1235677
... A2877: 46022 | B2877: 60.92 | C2877: 2192528 | D2877: 46.49 | E2877: 8257288 | F2877: 65.68 | G2877: 4529487 | H2877: 75.58 | I2877: 6231029 | J2877: 23.22 | K2877: 5113361 | L2877: 118.58 | M2877: 560782 | N2877: 52.33 | O2877: 1533798 | P2877: 61.57 | Q2877: 1313946 | R2877: 11.5 | S2877: 2819973 | T2877: 25.75 | U2877: 1630419

Sheet 2.2 Retornos
A6: FECHA | B6: RY | C6: TD | D6: BMO | E6: BNS | F6: CM | G6: NA | H6: BN | I6: MFC | J6: SLF | K6: GWO | L6: Retorno índice financiero | M6: ABX | N6: AEM | O6: LUG | P6: WPM | Q6: FNV | R6: TECK B | S6: K | T6: FM | U6: LUN | V6: PAAS | W6: Retorno Índice Materiales | X6: SU | Y6: CNQ | Z6: ENB | AA6: TRP | AB6: CVE | AC6: IMO | AD6: PPL | AE6: TOU | AF6: WCP | AG6: ARX | AH6: Retorno de índice Energía
A7: =S.FINANCIERO!A7 -> 42005
A8: =S.FINANCIERO!A8 -> 42006 | B8: =S.FINANCIERO!B8/S.FINANCIERO!B7-1 -> 0.0057328016 | C8: =S.FINANCIERO!D8/S.FINANCIERO!D7-1 -> -0.0052242839 | D8: =S.FINANCIERO!F8/S.FINANCIERO!F7-1 -> 0.004502312 | E8: =S.FINANCIERO!H8/S.FINANCIERO!H7-1 -> -0.011612125 | F8: =S.FINANCIERO!J8/S.FINANCIERO!J7-1 -> 0.0052083333 | G8: =S.FINANCIERO!L8/S.FINANCIERO!L7-1 -> 0.012338188 | H8: =S.FINANCIERO!N8/S.FINANCIERO!N7-1 -> 0.01649017 | I8: =S.FINANCIERO!P8/S.FINANCIERO!P7-1 -> 0.0027051398 | J8: =S.FINANCIERO!R8/S.FINANCIERO!R7-1 -> 0.0047709924 | K8: =S.FINANCIERO!T8/S.FINANCIERO!T7-1 -> -0.0020839536 | L8: =SUMPRODUCT(B8:K8, 'Ponderaciones e Índices.'!$A$4:$J$4) -> 0.0025319483 | M8: ='S. MATERIALES'!B8/'S. MATERIALES'!B7-1 -> 0.02715655 | N8: ='S. MATERIALES'!D8/'S. MATERIALES'!D7-1 -> 0.096818811 | O8: ='S. MATERIALES'!F8/'S. MATERIALES'!F7-1 -> -0.016777165 | P8: ='S. MATERIALES'!H8/'S. MATERIALES'!H7-1 -> 0.038087177 | Q8: ='S. MATERIALES'!J8/'S. MATERIALES'!J7-1 -> 0.0094389093 | R8: ='S. MATERIALES'!L8/'S. MATERIALES'!L7-1 -> 0.015743073 | S8: ='S. MATERIALES'!N8/'S. MATERIALES'!N7-1 -> 0.049079755 | T8: ='S. MATERIALES'!P8/'S. MATERIALES'!P7-1 -> 0.047244094 | U8: ='S. MATERIALES'!R8/'S. MATERIALES'!R7-1 -> 0.019230769 | V8: ='S. MATERIALES'!T8/'S. MATERIALES'!T7-1 -> 0.050373134 | W8: =SUMPRODUCT(M8:V8,'Ponderaciones e Índices.'!$A$8:$J$8) -> 0.035070261 | X8: ='S. ENERGÍA'!B8/'S. ENERGÍA'!B7-1 -> 0.012195122 | Y8: ='S. ENERGÍA'!D8/'S. ENERGÍA'!D7-1 -> 0.010301194 | Z8: ='S. ENERGÍA'!F8/'S. ENERGÍA'!F7-1 -> 0.011884834 | AA8: ='S. ENERGÍA'!H8/'S. ENERGÍA'!H7-1 -> 0.016112102 | AB8: ='S. ENERGÍA'!J8/'S. ENERGÍA'!J7-1 -> 0.017104714 | AC8: ='S. ENERGÍA'!L8/'S. ENERGÍA'!L7-1 -> 0.0025974026 | AD8: ='S. ENERGÍA'!N8/'S. ENERGÍA'!N7-1 -> 0.023854511 | AE8: ='S. ENERGÍA'!P8/'S. ENERGÍA'!P7-1 -> 0.032041344 | AF8: ='S. ENERGÍA'!R8/'S. ENERGÍA'!R7-1 -> 0.020979021 | AG8: ='S. ENERGÍA'!T8/'S. ENERGÍA'!T7-1 -> 0.023449921 | AH8: =SUMPRODUCT(X8:AG8,'Ponderaciones e Índices.'!$A$12:$J$12) -> 0.014610812
A9: =S.FINANCIERO!A9 -> 42009 | B9: =S.FINANCIERO!B9/S.FINANCIERO!B8-1 -> -0.022552664 | C9: =S.FINANCIERO!D9/S.FINANCIERO!D8-1 -> -0.023180007 | D9: =S.FINANCIERO!F9/S.FINANCIERO!F8-1 -> -0.022289521 | E9: =S.FINANCIERO!H9/S.FINANCIERO!H8-1 -> -0.019072322 | F9: =S.FINANCIERO!J9/S.FINANCIERO!J8-1 -> -0.019728976 | G9: =S.FINANCIERO!L9/S.FINANCIERO!L8-1 -> -0.048951049 | H9: =S.FINANCIERO!N9/S.FINANCIERO!N8-1 -> -0.0096310736 | I9: =S.FINANCIERO!P9/S.FINANCIERO!P8-1 -> -0.026528777 | J9: =S.FINANCIERO!R9/S.FINANCIERO!R8-1 -> -0.020180437 | K9: =S.FINANCIERO!T9/S.FINANCIERO!T8-1 -> -0.00924821 | L9: =SUMPRODUCT(B9:K9, 'Ponderaciones e Índices.'!$A$4:$J$4) -> -0.022559157 | M9: ='S. MATERIALES'!B9/'S. MATERIALES'!B8-1 -> -0.0038880249 | N9: ='S. MATERIALES'!D9/'S. MATERIALES'!D8-1 -> 0.015132409 | O9: ='S. MATERIALES'!F9/'S. MATERIALES'!F8-1 -> -0.017089178 | P9: ='S. MATERIALES'!H9/'S. MATERIALES'!H8-1 -> 0.011822258 | Q9: ='S. MATERIALES'!J9/'S. MATERIALES'!J8-1 -> 0.052467532 | R9: ='S. MATERIALES'!L9/'S. MATERIALES'!L8-1 -> -0.034717917 | S9: ='S. MATERIALES'!N9/'S. MATERIALES'!N8-1 -> 0.01754386 | T9: ='S. MATERIALES'!P9/'S. MATERIALES'!P8-1 -> -0.083285136 | U9: ='S. MATERIALES'!R9/'S. MATERIALES'!R8-1 -> -0.041166381 | V9: ='S. MATERIALES'!T9/'S. MATERIALES'!T8-1 -> 0.031083481 | W9: =SUMPRODUCT(M9:V9,'Ponderaciones e Índices.'!$A$8:$J$8) -> -0.019847585 | X9: ='S. ENERGÍA'!B9/'S. ENERGÍA'!B8-1 -> -0.043641232 | Y9: ='S. ENERGÍA'!D9/'S. ENERGÍA'!D8-1 -> -0.068614696 | Z9: ='S. ENERGÍA'!F9/'S. ENERGÍA'!F8-1 -> -0.038709677 | AA9: ='S. ENERGÍA'!H9/'S. ENERGÍA'!H8-1 -> -0.037744845 | AB9: ='S. ENERGÍA'!J9/'S. ENERGÍA'!J8-1 -> -0.052502051 | AC9: ='S. ENERGÍA'!L9/'S. ENERGÍA'!L8-1 -> -0.043443603 | AD9: ='S. ENERGÍA'!N9/'S. ENERGÍA'!N8-1 -> -0.050749712 | AE9: ='S. ENERGÍA'!P9/'S. ENERGÍA'!P8-1 -> -0.055082624 | AF9: ='S. ENERGÍA'!R9/'S. ENERGÍA'!R8-1 -> -0.098458904 | AG9: ='S. ENERGÍA'!T9/'S. ENERGÍA'!T8-1 -> -0.079223301 | AH9: =SUMPRODUCT(X9:AG9,'Ponderaciones e Índices.'!$A$12:$J$12) -> -0.061235333
A10: =S.FINANCIERO!A10 -> 42010 | B10: =S.FINANCIERO!B10/S.FINANCIERO!B9-1 -> -0.0070993915 | C10: =S.FINANCIERO!D10/S.FINANCIERO!D9-1 -> -0.016314423 | D10: =S.FINANCIERO!F10/S.FINANCIERO!F9-1 -> -0.013876843 | E10: =S.FINANCIERO!H10/S.FINANCIERO!H9-1 -> -0.012443615 | F10: =S.FINANCIERO!J10/S.FINANCIERO!J9-1 -> -0.027038016 | G10: =S.FINANCIERO!L10/S.FINANCIERO!L9-1 -> -0.0018907563 | H10: =S.FINANCIERO!N10/S.FINANCIERO!N9-1 -> -0.0056350965 | I10: =S.FINANCIERO!P10/S.FINANCIERO!P9-1 -> -0.02448037 | J10: =S.FINANCIERO!R10/S.FINANCIERO!R9-1 -> -0.031015265 | K10: =S.FINANCIERO!T10/S.FINANCIERO!T9-1 -> -0.017765733 | L10: =SUMPRODUCT(B10:K10, 'Ponderaciones e Índices.'!$A$4:$J$4) -> -0.015740261 | M10: ='S. MATERIALES'!B10/'S. MATERIALES'!B9-1 -> 0.039032006 | N10: ='S. MATERIALES'!D10/'S. MATERIALES'!D9-1 -> 0.061180124 | O10: ='S. MATERIALES'!F10/'S. MATERIALES'!F9-1 -> 0.032258909 | P10: ='S. MATERIALES'!H10/'S. MATERIALES'!H9-1 -> 0.039887188 | Q10: ='S. MATERIALES'!J10/'S. MATERIALES'!J9-1 -> 0.021059559 | R10: ='S. MATERIALES'!L10/'S. MATERIALES'!L9-1 -> 0.00064226076 | S10: ='S. MATERIALES'!N10/'S. MATERIALES'!N9-1 -> 0.13505747 | T10: ='S. MATERIALES'!P10/'S. MATERIALES'!P9-1 -> 0.026498423 | U10: ='S. MATERIALES'!R10/'S. MATERIALES'!R9-1 -> -0.0035778175 | V10: ='S. MATERIALES'!T10/'S. MATERIALES'!T9-1 -> 0.042204996 | W10: =SUMPRODUCT(M10:V10,'Ponderaciones e Índices.'!$A$8:$J$8) -> 0.039142407 | X10: ='S. ENERGÍA'!B10/'S. ENERGÍA'!B9-1 -> -0.013717805 | Y10: ='S. ENERGÍA'!D10/'S. ENERGÍA'!D9-1 -> -0.02899298 | Z10: ='S. ENERGÍA'!F10/'S. ENERGÍA'!F9-1 -> -0.036138358 | AA10: ='S. ENERGÍA'!H10/'S. ENERGÍA'!H9-1 -> -0.029016966 | AB10: ='S. ENERGÍA'!J10/'S. ENERGÍA'!J9-1 -> 0.00086580087 | AC10: ='S. ENERGÍA'!L10/'S. ENERGÍA'!L9-1 -> -0.016041667 | AD10: ='S. ENERGÍA'!N10/'S. ENERGÍA'!N9-1 -> -0.022843256 | AE10: ='S. ENERGÍA'!P10/'S. ENERGÍA'!P9-1 -> -0.029941706 | AF10: ='S. ENERGÍA'!R10/'S. ENERGÍA'!R9-1 -> -0.018993352 | AG10: ='S. ENERGÍA'!T10/'S. ENERGÍA'!T9-1 -> -0.013496415 | AH10: =SUMPRODUCT(X10:AG10,'Ponderaciones e Índices.'!$A$12:$J$12) -> -0.021188102
A11: =S.FINANCIERO!A11 -> 42011 | B11: =S.FINANCIERO!B11/S.FINANCIERO!B10-1 -> 0.00038304392 | C11: =S.FINANCIERO!D11/S.FINANCIERO!D10-1 -> -0.0032039201 | D11: =S.FINANCIERO!F11/S.FINANCIERO!F10-1 -> -0.00037693178 | E11: =S.FINANCIERO!H11/S.FINANCIERO!H10-1 -> 0.0028350921 | F11: =S.FINANCIERO!J11/S.FINANCIERO!J10-1 -> -0.00094024237 | G11: =S.FINANCIERO!L11/S.FINANCIERO!L10-1 -> 0.012207956 | H11: =S.FINANCIERO!N11/S.FINANCIERO!N10-1 -> 0.017162379 | I11: =S.FINANCIERO!P11/S.FINANCIERO!P10-1 -> 0.0066287879 | J11: =S.FINANCIERO!R11/S.FINANCIERO!R10-1 -> 0.016504126 | K11: =S.FINANCIERO!T11/S.FINANCIERO!T10-1 -> -0.00091968118 | L11: =SUMPRODUCT(B11:K11, 'Ponderaciones e Índices.'!$A$4:$J$4) -> 0.0040562305 | M11: ='S. MATERIALES'!B11/'S. MATERIALES'!B10-1 -> -0.012021037 | N11: ='S. MATERIALES'!D11/'S. MATERIALES'!D10-1 -> -0.01404741 | O11: ='S. MATERIALES'!F11/'S. MATERIALES'!F10-1 -> 0.0096136773 | P11: ='S. MATERIALES'!H11/'S. MATERIALES'!H10-1 -> -0.02130957 | Q11: ='S. MATERIALES'!J11/'S. MATERIALES'!J10-1 -> -0.019336126 | R11: ='S. MATERIALES'!L11/'S. MATERIALES'!L10-1 -> -0.001283697 | S11: ='S. MATERIALES'!N11/'S. MATERIALES'!N10-1 -> -0.030379747 | T11: ='S. MATERIALES'!P11/'S. MATERIALES'!P10-1 -> -0.0086047941 | U11: ='S. MATERIALES'!R11/'S. MATERIALES'!R10-1 -> -0.021543986 | V11: ='S. MATERIALES'!T11/'S. MATERIALES'!T10-1 -> -0.01322314 | W11: =SUMPRODUCT(M11:V11,'Ponderaciones e Índices.'!$A$8:$J$8) -> -0.016205383 | X11: ='S. ENERGÍA'!B11/'S. ENERGÍA'!B10-1 -> 0.001419245 | Y11: ='S. ENERGÍA'!D11/'S. ENERGÍA'!D10-1 -> -0.019504455 | Z11: ='S. ENERGÍA'!F11/'S. ENERGÍA'!F10-1 -> -0.0087484378 | AA11: ='S. ENERGÍA'!H11/'S. ENERGÍA'!H10-1 -> -0.0057184397 | AB11: ='S. ENERGÍA'!J11/'S. ENERGÍA'!J10-1 -> -0.008650519 | AC11: ='S. ENERGÍA'!L11/'S. ENERGÍA'!L10-1 -> 0.0033876773 | AD11: ='S. ENERGÍA'!N11/'S. ENERGÍA'!N10-1 -> -0.016413827 | AE11: ='S. ENERGÍA'!P11/'S. ENERGÍA'!P10-1 -> 0.016662114 | AF11: ='S. ENERGÍA'!R11/'S. ENERGÍA'!R10-1 -> 0.0048402711 | AG11: ='S. ENERGÍA'!T11/'S. ENERGÍA'!T10-1 -> -0.0021376657 | AH11: =SUMPRODUCT(X11:AG11,'Ponderaciones e Índices.'!$A$12:$J$12) -> -0.007940622
A12: =S.FINANCIERO!A12 -> 42012 | B12: =S.FINANCIERO!B12/S.FINANCIERO!B11-1 -> 0.0061263561 | C12: =S.FINANCIERO!D12/S.FINANCIERO!D11-1 -> 0.0064284364 | D12: =S.FINANCIERO!F12/S.FINANCIERO!F11-1 -> 0 | E12: =S.FINANCIERO!H12/S.FINANCIERO!H11-1 -> 0.0080100518 | F12: =S.FINANCIERO!J12/S.FINANCIERO!J11-1 -> -0.0044964969 | G12: =S.FINANCIERO!L12/S.FINANCIERO!L11-1 -> 0.011644833 | H12: =S.FINANCIERO!N12/S.FINANCIERO!N11-1 -> 0.029183244 | I12: =S.FINANCIERO!P12/S.FINANCIERO!P11-1 -> 0.019755409 | J12: =S.FINANCIERO!R12/S.FINANCIERO!R11-1 -> 0.0036900369 | K12: =S.FINANCIERO!T12/S.FINANCIERO!T11-1 -> 0.0033752685 | L12: =SUMPRODUCT(B12:K12, 'Ponderaciones e Índices.'!$A$4:$J$4) -> 0.0092324335 | M12: ='S. MATERIALES'!B12/'S. MATERIALES'!B11-1 -> -0.027376426 | N12: ='S. MATERIALES'!D12/'S. MATERIALES'!D11-1 -> -0.016622143 | O12: ='S. MATERIALES'!F12/'S. MATERIALES'!F11-1 -> -0.011883825 | P12: ='S. MATERIALES'!H12/'S. MATERIALES'!H11-1 -> -0.011876485 | Q12: ='S. MATERIALES'!J12/'S. MATERIALES'!J11-1 -> -0.017581334 | R12: ='S. MATERIALES'!L12/'S. MATERIALES'!L11-1 -> 0.04562982 | S12: ='S. MATERIALES'!N12/'S. MATERIALES'!N11-1 -> 0.0052219321 | T12: ='S. MATERIALES'!P12/'S. MATERIALES'!P11-1 -> 0.065096094 | U12: ='S. MATERIALES'!R12/'S. MATERIALES'!R11-1 -> -0.0055045872 | V12: ='S. MATERIALES'!T12/'S. MATERIALES'!T11-1 -> -0.018425461 | W12: =SUMPRODUCT(M12:V12,'Ponderaciones e Índices.'!$A$8:$J$8) -> 0.0072650812 | X12: ='S. ENERGÍA'!B12/'S. ENERGÍA'!B11-1 -> 0.01984127 | Y12: ='S. ENERGÍA'!D12/'S. ENERGÍA'!D11-1 -> 0.028588701 | Z12: ='S. ENERGÍA'!F12/'S. ENERGÍA'!F11-1 -> 0.011167147 | AA12: ='S. ENERGÍA'!H12/'S. ENERGÍA'!H11-1 -> 0.019109318 | AB12: ='S. ENERGÍA'!J12/'S. ENERGÍA'!J11-1 -> 0.02617801 | AC12: ='S. ENERGÍA'!L12/'S. ENERGÍA'!L11-1 -> 0.015193079 | AD12: ='S. ENERGÍA'!N12/'S. ENERGÍA'!N11-1 -> 0.021238938 | AE12: ='S. ENERGÍA'!P12/'S. ENERGÍA'!P11-1 -> 0.0024180548 | AF12: ='S. ENERGÍA'!R12/'S. ENERGÍA'!R11-1 -> 0.022157996 | AG12: ='S. ENERGÍA'!T12/'S. ENERGÍA'!T11-1 -> -0.044558698 | AH12: =SUMPRODUCT(X12:AG12,'Ponderaciones e Índices.'!$A$12:$J$12) -> 0.01906619
A13: =S.FINANCIERO!A13 -> 42013 | B13: =S.FINANCIERO!B13/S.FINANCIERO!B12-1 -> -0.01712546 | C13: =S.FINANCIERO!D13/S.FINANCIERO!D12-1 -> -0.012211159 | D13: =S.FINANCIERO!F13/S.FINANCIERO!F12-1 -> -0.016214178 | E13: =S.FINANCIERO!H13/S.FINANCIERO!H12-1 -> -0.018229978 | F13: =S.FINANCIERO!J13/S.FINANCIERO!J12-1 -> -0.014285714 | G13: =S.FINANCIERO!L13/S.FINANCIERO!L12-1 -> -0.02713258 | H13: =S.FINANCIERO!N13/S.FINANCIERO!N12-1 -> -0.0026261792 | I13: =S.FINANCIERO!P13/S.FINANCIERO!P12-1 -> -0.016143911 | J13: =S.FINANCIERO!R13/S.FINANCIERO!R12-1 -> -0.015196078 | K13: =S.FINANCIERO!T13/S.FINANCIERO!T12-1 -> 0 | L13: =SUMPRODUCT(B13:K13, 'Ponderaciones e Índices.'!$A$4:$J$4) -> -0.014579256 | M13: ='S. MATERIALES'!B13/'S. MATERIALES'!B12-1 -> 0.019546521 | N13: ='S. MATERIALES'!D13/'S. MATERIALES'!D12-1 -> 0.065197706 | O13: ='S. MATERIALES'!F13/'S. MATERIALES'!F12-1 -> -0.012052175 | P13: ='S. MATERIALES'!H13/'S. MATERIALES'!H12-1 -> 0.032451923 | Q13: ='S. MATERIALES'!J13/'S. MATERIALES'!J12-1 -> 0.03261415 | R13: ='S. MATERIALES'!L13/'S. MATERIALES'!L12-1 -> -0.0073755378 | S13: ='S. MATERIALES'!N13/'S. MATERIALES'!N12-1 -> 0.062337662 | T13: ='S. MATERIALES'!P13/'S. MATERIALES'!P12-1 -> -0.015715949 | U13: ='S. MATERIALES'!R13/'S. MATERIALES'!R12-1 -> 0.0092250923 | V13: ='S. MATERIALES'!T13/'S. MATERIALES'!T12-1 -> 0.040955631 | W13: =SUMPRODUCT(M13:V13,'Ponderaciones e Índices.'!$A$8:$J$8) -> 0.019846645 | X13: ='S. ENERGÍA'!B13/'S. ENERGÍA'!B12-1 -> -0.010839355 | Y13: ='S. ENERGÍA'!D13/'S. ENERGÍA'!D12-1 -> 0.002118229 | Z13: ='S. ENERGÍA'!F13/'S. ENERGÍA'!F12-1 -> -0.014071963 | AA13: ='S. ENERGÍA'!H13/'S. ENERGÍA'!H12-1 -> 0.0074640288 | AB13: ='S. ENERGÍA'!J13/'S. ENERGÍA'!J12-1 -> 0.0097789116 | AC13: ='S. ENERGÍA'!L13/'S. ENERGÍA'!L12-1 -> -0.0047807109 | AD13: ='S. ENERGÍA'!N13/'S. ENERGÍA'!N12-1 -> -0.014607576 | AE13: ='S. ENERGÍA'!P13/'S. ENERGÍA'!P12-1 -> 0.0067006165 | AF13: ='S. ENERGÍA'!R13/'S. ENERGÍA'!R12-1 -> -0.00094250707 | AG13: ='S. ENERGÍA'!T13/'S. ENERGÍA'!T12-1 -> -0.0071748879 | AH13: =SUMPRODUCT(X13:AG13,'Ponderaciones e Índices.'!$A$12:$J$12) -> -0.0015422348
A14: =S.FINANCIERO!A14 -> 42016 | B14: =S.FINANCIERO!B14/S.FINANCIERO!B13-1 -> -0.0086473929 | C14: =S.FINANCIERO!D14/S.FINANCIERO!D13-1 -> -0.0098896919 | D14: =S.FINANCIERO!F14/S.FINANCIERO!F13-1 -> -0.0095822154 | E14: =S.FINANCIERO!H14/S.FINANCIERO!H13-1 -> -0.016664022 | F14: =S.FINANCIERO!J14/S.FINANCIERO!J13-1 -> -0.0079923274 | G14: =S.FINANCIERO!L14/S.FINANCIERO!L13-1 -> -0.03148109 | H14: =S.FINANCIERO!N14/S.FINANCIERO!N13-1 -> 0.0075622463 | I14: =S.FINANCIERO!P14/S.FINANCIERO!P13-1 -> 0 | J14: =S.FINANCIERO!R14/S.FINANCIERO!R13-1 -> -0.0032354405 | K14: =S.FINANCIERO!T14/S.FINANCIERO!T13-1 -> -0.0091743119 | L14: =SUMPRODUCT(B14:K14, 'Ponderaciones e Índices.'!$A$4:$J$4) -> -0.0081615552 | M14: ='S. MATERIALES'!B14/'S. MATERIALES'!B13-1 -> 0.041411043 | N14: ='S. MATERIALES'!D14/'S. MATERIALES'!D13-1 -> 0.048455653 | O14: ='S. MATERIALES'!F14/'S. MATERIALES'!F13-1 -> -0.0073349633 | P14: ='S. MATERIALES'!H14/'S. MATERIALES'!H13-1 -> 0.057043073 | Q14: ='S. MATERIALES'!J14/'S. MATERIALES'!J13-1 -> 0.049400713 | R14: ='S. MATERIALES'!L14/'S. MATERIALES'!L13-1 -> -0.034674923 | S14: ='S. MATERIALES'!N14/'S. MATERIALES'!N13-1 -> 0.012224939 | T14: ='S. MATERIALES'!P14/'S. MATERIALES'!P13-1 -> -0.0644589 | U14: ='S. MATERIALES'!R14/'S. MATERIALES'!R13-1 -> -0.056672761 | V14: ='S. MATERIALES'!T14/'S. MATERIALES'!T13-1 -> 0.049180328 | W14: =SUMPRODUCT(M14:V14,'Ponderaciones e Índices.'!$A$8:$J$8) -> -0.0083492534 | X14: ='S. ENERGÍA'!B14/'S. ENERGÍA'!B13-1 -> -0.035684181 | Y14: ='S. ENERGÍA'!D14/'S. ENERGÍA'!D13-1 -> -0.041004337 | Z14: ='S. ENERGÍA'!F14/'S. ENERGÍA'!F13-1 -> -0.01300813 | AA14: ='S. ENERGÍA'!H14/'S. ENERGÍA'!H13-1 -> -0.033068523 | AB14: ='S. ENERGÍA'!J14/'S. ENERGÍA'!J13-1 -> -0.031157895 | AC14: ='S. ENERGÍA'!L14/'S. ENERGÍA'!L13-1 -> -0.05304929 | AD14: ='S. ENERGÍA'!N14/'S. ENERGÍA'!N13-1 -> -0.024623116 | AE14: ='S. ENERGÍA'!P14/'S. ENERGÍA'!P13-1 -> -0.047390841 | AF14: ='S. ENERGÍA'!R14/'S. ENERGÍA'!R13-1 -> -0.075471698 | AG14: ='S. ENERGÍA'!T14/'S. ENERGÍA'!T13-1 -> -0.0532972 | AH14: =SUMPRODUCT(X14:AG14,'Ponderaciones e Índices.'!$A$12:$J$12) -> -0.041420563
A15: =S.FINANCIERO!A15 -> 42017 | B15: =S.FINANCIERO!B15/S.FINANCIERO!B14-1 -> -0.0014321052 | C15: =S.FINANCIERO!D15/S.FINANCIERO!D14-1 -> -0.0017287745 | D15: =S.FINANCIERO!F15/S.FINANCIERO!F14-1 -> -0.015350877 | E15: =S.FINANCIERO!H15/S.FINANCIERO!H14-1 -> -0.00064557779 | F15: =S.FINANCIERO!J15/S.FINANCIERO!J14-1 -> 0.0071973359 | G15: =S.FINANCIERO!L15/S.FINANCIERO!L14-1 -> 0.00043630017 | H15: =S.FINANCIERO!N15/S.FINANCIERO!N14-1 -> 0.022837033 | I15: =S.FINANCIERO!P15/S.FINANCIERO!P14-1 -> -0.0070323488 | J15: =S.FINANCIERO!R15/S.FINANCIERO!R14-1 -> -0.0019975031 | K15: =S.FINANCIERO!T15/S.FINANCIERO!T14-1 -> 0.0040123457 | L15: =SUMPRODUCT(B15:K15, 'Ponderaciones e Índices.'!$A$4:$J$4) -> 0.00056012068 | M15: ='S. MATERIALES'!B15/'S. MATERIALES'!B14-1 -> -0.060382916 | N15: ='S. MATERIALES'!D15/'S. MATERIALES'!D14-1 -> -0.039189189 | O15: ='S. MATERIALES'!F15/'S. MATERIALES'!F14-1 -> -0.034379051 | P15: ='S. MATERIALES'!H15/'S. MATERIALES'!H14-1 -> -0.013215859 | Q15: ='S. MATERIALES'!J15/'S. MATERIALES'!J14-1 -> -0.049235993 | R15: ='S. MATERIALES'!L15/'S. MATERIALES'!L14-1 -> -0.059653624 | S15: ='S. MATERIALES'!N15/'S. MATERIALES'!N14-1 -> -0.079710145 | T15: ='S. MATERIALES'!P15/'S. MATERIALES'!P14-1 -> -0.14854614 | U15: ='S. MATERIALES'!R15/'S. MATERIALES'!R14-1 -> -0.093023256 | V15: ='S. MATERIALES'!T15/'S. MATERIALES'!T14-1 -> -0.02734375 | W15: =SUMPRODUCT(M15:V15,'Ponderaciones e Índices.'!$A$8:$J$8) -> -0.078251286 | X15: ='S. ENERGÍA'!B15/'S. ENERGÍA'!B14-1 -> 0.014277389 | Y15: ='S. ENERGÍA'!D15/'S. ENERGÍA'!D14-1 -> 0.0040897451 | Z15: ='S. ENERGÍA'!F15/'S. ENERGÍA'!F14-1 -> -0.021233754 | AA15: ='S. ENERGÍA'!H15/'S. ENERGÍA'!H14-1 -> -0.01887524 | AB15: ='S. ENERGÍA'!J15/'S. ENERGÍA'!J14-1 -> -0.011299435 | AC15: ='S. ENERGÍA'!L15/'S. ENERGÍA'!L14-1 -> -0.010586678 | AD15: ='S. ENERGÍA'!N15/'S. ENERGÍA'!N14-1 -> -0.040958269 | AE15: ='S. ENERGÍA'!P15/'S. ENERGÍA'!P14-1 -> 0.0044717719 | AF15: ='S. ENERGÍA'!R15/'S. ENERGÍA'!R14-1 -> 0.020408163 | AG15: ='S. ENERGÍA'!T15/'S. ENERGÍA'!T14-1 -> 0.040553435 | AH15: =SUMPRODUCT(X15:AG15,'Ponderaciones e Índices.'!$A$12:$J$12) -> 0.0026205773
A16: =S.FINANCIERO!A16 -> 42018 | B16: =S.FINANCIERO!B16/S.FINANCIERO!B15-1 -> -0.013298566 | C16: =S.FINANCIERO!D16/S.FINANCIERO!D15-1 -> -0.027515875 | D16: =S.FINANCIERO!F16/S.FINANCIERO!F15-1 -> -0.013363029 | E16: =S.FINANCIERO!H16/S.FINANCIERO!H15-1 -> -0.0043604651 | F16: =S.FINANCIERO!J16/S.FINANCIERO!J15-1 -> -0.018238055 | G16: =S.FINANCIERO!L16/S.FINANCIERO!L15-1 -> -0.018316616 | H16: =S.FINANCIERO!N16/S.FINANCIERO!N15-1 -> -0.01116698 | I16: =S.FINANCIERO!P16/S.FINANCIERO!P15-1 -> -0.039187913 | J16: =S.FINANCIERO!R16/S.FINANCIERO!R15-1 -> -0.047785839 | K16: =S.FINANCIERO!T16/S.FINANCIERO!T15-1 -> -0.021518598 | L16: =SUMPRODUCT(B16:K16, 'Ponderaciones e Índices.'!$A$4:$J$4) -> -0.021188683 | M16: ='S. MATERIALES'!B16/'S. MATERIALES'!B15-1 -> -0.027429467 | N16: ='S. MATERIALES'!D16/'S. MATERIALES'!D15-1 -> -0.012658228 | O16: ='S. MATERIALES'!F16/'S. MATERIALES'!F15-1 -> -0.050907529 | P16: ='S. MATERIALES'!H16/'S. MATERIALES'!H15-1 -> -0.0070684524 | Q16: ='S. MATERIALES'!J16/'S. MATERIALES'!J15-1 -> -0.020454545 | R16: ='S. MATERIALES'!L16/'S. MATERIALES'!L15-1 -> -0.065484311 | S16: ='S. MATERIALES'!N16/'S. MATERIALES'!N15-1 -> -0.0026246719 | T16: ='S. MATERIALES'!P16/'S. MATERIALES'!P15-1 -> -0.13140312 | U16: ='S. MATERIALES'!R16/'S. MATERIALES'!R15-1 -> -0.10683761 | V16: ='S. MATERIALES'!T16/'S. MATERIALES'!T15-1 -> -0.01124498 | W16: =SUMPRODUCT(M16:V16,'Ponderaciones e Índices.'!$A$8:$J$8) -> -0.058510254 | X16: ='S. ENERGÍA'!B16/'S. ENERGÍA'!B15-1 -> 0.0017236426 | Y16: ='S. ENERGÍA'!D16/'S. ENERGÍA'!D15-1 -> 0.026614643 | Z16: ='S. ENERGÍA'!F16/'S. ENERGÍA'!F15-1 -> 0.0074808304 | AA16: ='S. ENERGÍA'!H16/'S. ENERGÍA'!H15-1 -> 0.0017145378 | AB16: ='S. ENERGÍA'!J16/'S. ENERGÍA'!J15-1 -> 0.025054945 | AC16: ='S. ENERGÍA'!L16/'S. ENERGÍA'!L15-1 -> 0.0073562193 | AD16: ='S. ENERGÍA'!N16/'S. ENERGÍA'!N15-1 -> 0.025785657 | AE16: ='S. ENERGÍA'!P16/'S. ENERGÍA'!P15-1 -> 0.03116305 | AF16: ='S. ENERGÍA'!R16/'S. ENERGÍA'!R15-1 -> 0.032 | AG16: ='S. ENERGÍA'!T16/'S. ENERGÍA'!T15-1 -> 0.027051811 | AH16: =SUMPRODUCT(X16:AG16,'Ponderaciones e Índices.'!$A$12:$J$12) -> 0.019747293
A17: =S.FINANCIERO!A17 -> 42019 | B17: =S.FINANCIERO!B17/S.FINANCIERO!B16-1 -> -0.0073995772 | C17: =S.FINANCIERO!D17/S.FINANCIERO!D16-1 -> -0.012564305 | D17: =S.FINANCIERO!F17/S.FINANCIERO!F16-1 -> -0.0011950604 | E17: =S.FINANCIERO!H17/S.FINANCIERO!H16-1 -> -0.005028386 | F17: =S.FINANCIERO!J17/S.FINANCIERO!J16-1 -> -0.0060836502 | G17: =S.FINANCIERO!L17/S.FINANCIERO!L16-1 -> -0.002665482 | H17: =S.FINANCIERO!N17/S.FINANCIERO!N16-1 -> -0.006125416 | I17: =S.FINANCIERO!P17/S.FINANCIERO!P16-1 -> -0.022604423 | J17: =S.FINANCIERO!R17/S.FINANCIERO!R16-1 -> -0.017078297 | K17: =S.FINANCIERO!T17/S.FINANCIERO!T16-1 -> -0.016336789 | L17: =SUMPRODUCT(B17:K17, 'Ponderaciones e Índices.'!$A$4:$J$4) -> -0.0098956902 | M17: ='S. MATERIALES'!B17/'S. MATERIALES'!B16-1 -> 0.095890411 | N17: ='S. MATERIALES'!D17/'S. MATERIALES'!D16-1 -> 0.06980057 | O17: ='S. MATERIALES'!F17/'S. MATERIALES'!F16-1 -> 0.032194184 | P17: ='S. MATERIALES'!H17/'S. MATERIALES'!H16-1 -> 0.022105658 | Q17: ='S. MATERIALES'!J17/'S. MATERIALES'!J16-1 -> 0.060987736 | R17: ='S. MATERIALES'!L17/'S. MATERIALES'!L16-1 -> -0.0094890511 | S17: ='S. MATERIALES'!N17/'S. MATERIALES'!N16-1 -> 0.11052632 | T17: ='S. MATERIALES'!P17/'S. MATERIALES'!P16-1 -> 0.021367521 | U17: ='S. MATERIALES'!R17/'S. MATERIALES'!R16-1 -> -0.009569378 | V17: ='S. MATERIALES'!T17/'S. MATERIALES'!T16-1 -> 0.040617384 | W17: =SUMPRODUCT(M17:V17,'Ponderaciones e Índices.'!$A$8:$J$8) -> 0.042173494 | X17: ='S. ENERGÍA'!B17/'S. ENERGÍA'!B16-1 -> -0.018640665 | Y17: ='S. ENERGÍA'!D17/'S. ENERGÍA'!D16-1 -> -0.0042703087 | Z17: ='S. ENERGÍA'!F17/'S. ENERGÍA'!F16-1 -> 0.00055689623 | AA17: ='S. ENERGÍA'!H17/'S. ENERGÍA'!H16-1 -> -0.013310846 | AB17: ='S. ENERGÍA'!J17/'S. ENERGÍA'!J16-1 -> -0.010720412 | AC17: ='S. ENERGÍA'!L17/'S. ENERGÍA'!L16-1 -> -0.0055321974 | AD17: ='S. ENERGÍA'!N17/'S. ENERGÍA'!N16-1 -> -0.024351925 | AE17: ='S. ENERGÍA'!P17/'S. ENERGÍA'!P16-1 -> 0.014301133 | AF17: ='S. ENERGÍA'!R17/'S. ENERGÍA'!R16-1 -> -0.0067829457 | AG17: ='S. ENERGÍA'!T17/'S. ENERGÍA'!T16-1 -> -0.020982143 | AH17: =SUMPRODUCT(X17:AG17,'Ponderaciones e Índices.'!$A$12:$J$12) -> -0.0092689538
A18: =S.FINANCIERO!A18 -> 42020 | B18: =S.FINANCIERO!B18/S.FINANCIERO!B17-1 -> 0.0051916933 | C18: =S.FINANCIERO!D18/S.FINANCIERO!D17-1 -> 0.0061116121 | D18: =S.FINANCIERO!F18/S.FINANCIERO!F17-1 -> 0.0061153948 | E18: =S.FINANCIERO!H18/S.FINANCIERO!H17-1 -> 0.0045647212 | F18: =S.FINANCIERO!J18/S.FINANCIERO!J17-1 -> -0.0099464422 | G18: =S.FINANCIERO!L18/S.FINANCIERO!L17-1 -> -0.0053452116 | H18: =S.FINANCIERO!N18/S.FINANCIERO!N17-1 -> 0.00210754 | I18: =S.FINANCIERO!P18/S.FINANCIERO!P17-1 -> 0.017094017 | J18: =S.FINANCIERO!R18/S.FINANCIERO!R17-1 -> 0.0016038492 | K18: =S.FINANCIERO!T18/S.FINANCIERO!T17-1 -> 0.0054295752 | L18: =SUMPRODUCT(B18:K18, 'Ponderaciones e Índices.'!$A$4:$J$4) -> 0.0040336823 | M18: ='S. MATERIALES'!B18/'S. MATERIALES'!B17-1 -> 0.036029412 | N18: ='S. MATERIALES'!D18/'S. MATERIALES'!D17-1 -> 0.040213049 | O18: ='S. MATERIALES'!F18/'S. MATERIALES'!F17-1 -> 0.012963877 | P18: ='S. MATERIALES'!H18/'S. MATERIALES'!H17-1 -> 0.023460411 | Q18: ='S. MATERIALES'!J18/'S. MATERIALES'!J17-1 -> 0.03030303 | R18: ='S. MATERIALES'!L18/'S. MATERIALES'!L17-1 -> 0.04642594 | S18: ='S. MATERIALES'!N18/'S. MATERIALES'!N17-1 -> 0.016587678 | T18: ='S. MATERIALES'!P18/'S. MATERIALES'!P17-1 -> 0.11129707 | U18: ='S. MATERIALES'!R18/'S. MATERIALES'!R17-1 -> 0.072463768 | V18: ='S. MATERIALES'!T18/'S. MATERIALES'!T17-1 -> 0.026541764 | W18: =SUMPRODUCT(M18:V18,'Ponderaciones e Índices.'!$A$8:$J$8) -> 0.052418289 | X18: ='S. ENERGÍA'!B18/'S. ENERGÍA'!B17-1 -> 0.052016365 | Y18: ='S. ENERGÍA'!D18/'S. ENERGÍA'!D17-1 -> 0.087590924 | Z18: ='S. ENERGÍA'!F18/'S. ENERGÍA'!F17-1 -> 0.049165121 | AA18: ='S. ENERGÍA'!H18/'S. ENERGÍA'!H17-1 -> 0.022741408 | AB18: ='S. ENERGÍA'!J18/'S. ENERGÍA'!J17-1 -> 0.068053749 | AC18: ='S. ENERGÍA'!L18/'S. ENERGÍA'!L17-1 -> 0.05540721 | AD18: ='S. ENERGÍA'!N18/'S. ENERGÍA'!N17-1 -> 0.022275899 | AE18: ='S. ENERGÍA'!P18/'S. ENERGÍA'!P17-1 -> 0.014897579 | AF18: ='S. ENERGÍA'!R18/'S. ENERGÍA'!R17-1 -> 0.084878049 | AG18: ='S. ENERGÍA'!T18/'S. ENERGÍA'!T17-1 -> 0.011399909 | AH18: =SUMPRODUCT(X18:AG18,'Ponderaciones e Índices.'!$A$12:$J$12) -> 0.063108964
A19: =S.FINANCIERO!A19 -> 42023 | B19: =S.FINANCIERO!B19/S.FINANCIERO!B18-1 -> 0.0038405509 | C19: =S.FINANCIERO!D19/S.FINANCIERO!D18-1 -> 0.0065723959 | D19: =S.FINANCIERO!F19/S.FINANCIERO!F18-1 -> -0.0026427061 | E19: =S.FINANCIERO!H19/S.FINANCIERO!H18-1 -> 0.00048685492 | F19: =S.FINANCIERO!J19/S.FINANCIERO!J18-1 -> 0.0038639876 | G19: =S.FINANCIERO!L19/S.FINANCIERO!L18-1 -> 0.010300045 | H19: =S.FINANCIERO!N19/S.FINANCIERO!N18-1 -> -0.01311675 | I19: =S.FINANCIERO!P19/S.FINANCIERO!P18-1 -> 0.0034602076 | J19: =S.FINANCIERO!R19/S.FINANCIERO!R18-1 -> 0.011475847 | K19: =S.FINANCIERO!T19/S.FINANCIERO!T18-1 -> 0.00095298602 | L19: =SUMPRODUCT(B19:K19, 'Ponderaciones e Índices.'!$A$4:$J$4) -> 0.0024442627 | M19: ='S. MATERIALES'!B19/'S. MATERIALES'!B18-1 -> 0.0085166785 | N19: ='S. MATERIALES'!D19/'S. MATERIALES'!D18-1 -> -0.0030721966 | O19: ='S. MATERIALES'!F19/'S. MATERIALES'!F18-1 -> -0.0051137747 | P19: ='S. MATERIALES'!H19/'S. MATERIALES'!H18-1 -> 0.011819484 | Q19: ='S. MATERIALES'!J19/'S. MATERIALES'!J18-1 -> -0.00030321407 | R19: ='S. MATERIALES'!L19/'S. MATERIALES'!L18-1 -> 0.014788732 | S19: ='S. MATERIALES'!N19/'S. MATERIALES'!N18-1 -> 0.0046620047 | T19: ='S. MATERIALES'!P19/'S. MATERIALES'!P18-1 -> 0.0090361446 | U19: ='S. MATERIALES'!R19/'S. MATERIALES'!R18-1 -> -0.013513514 | V19: ='S. MATERIALES'!T19/'S. MATERIALES'!T18-1 -> 0.0091254753 | W19: =SUMPRODUCT(M19:V19,'Ponderaciones e Índices.'!$A$8:$J$8) -> 0.0030766028 | X19: ='S. ENERGÍA'!B19/'S. ENERGÍA'!B18-1 -> -0.0125 | Y19: ='S. ENERGÍA'!D19/'S. ENERGÍA'!D18-1 -> -0.030975194 | Z19: ='S. ENERGÍA'!F19/'S. ENERGÍA'!F18-1 -> -0.009372237 | AA19: ='S. ENERGÍA'!H19/'S. ENERGÍA'!H18-1 -> 0.0020725774 | AB19: ='S. ENERGÍA'!J19/'S. ENERGÍA'!J18-1 -> -0.034090909 | AC19: ='S. ENERGÍA'!L19/'S. ENERGÍA'!L18-1 -> -0.024035421 | AD19: ='S. ENERGÍA'!N19/'S. ENERGÍA'!N18-1 -> -0.0002625361 | AE19: ='S. ENERGÍA'!P19/'S. ENERGÍA'!P18-1 -> 0.0023591088 | AF19: ='S. ENERGÍA'!R19/'S. ENERGÍA'!R18-1 -> -0.0053956835 | AG19: ='S. ENERGÍA'!T19/'S. ENERGÍA'!T18-1 -> 0.0090171326 | AH19: =SUMPRODUCT(X19:AG19,'Ponderaciones e Índices.'!$A$12:$J$12) -> -0.017303412
... A28: =S.FINANCIERO!A28 -> 42034 | B28: =S.FINANCIERO!B28/S.FINANCIERO!B27-1 -> -0.03197949 | C28: =S.FINANCIERO!D28/S.FINANCIERO!D27-1 -> -0.020139427 | D28: =S.FINANCIERO!F28/S.FINANCIERO!F27-1 -> -0.04224613 | E28: =S.FINANCIERO!H28/S.FINANCIERO!H27-1 -> -0.022727273 | F28: =S.FINANCIERO!J28/S.FINANCIERO!J27-1 -> -0.034912991 | G28: =S.FINANCIERO!L28/S.FINANCIERO!L27-1 -> -0.029418222 | H28: =S.FINANCIERO!N28/S.FINANCIERO!N27-1 -> -0.0066009846 | I28: =S.FINANCIERO!P28/S.FINANCIERO!P27-1 -> -0.015063168 | J28: =S.FINANCIERO!R28/S.FINANCIERO!R27-1 -> -0.0035897436 | K28: =S.FINANCIERO!T28/S.FINANCIERO!T27-1 -> -0.011053116 | L28: =SUMPRODUCT(B28:K28, 'Ponderaciones e Índices.'!$A$4:$J$4) -> -0.022775396 | M28: ='S. MATERIALES'!B28/'S. MATERIALES'!B27-1 -> 0.049063912 | N28: ='S. MATERIALES'!D28/'S. MATERIALES'!D27-1 -> 0.038797284 | O28: ='S. MATERIALES'!F28/'S. MATERIALES'!F27-1 -> 0.0025061334 | P28: ='S. MATERIALES'!H28/'S. MATERIALES'!H27-1 -> 0.039900249 | Q28: ='S. MATERIALES'!J28/'S. MATERIALES'!J27-1 -> 0.06337007 | R28: ='S. MATERIALES'!L28/'S. MATERIALES'!L27-1 -> 0.045108005 | S28: ='S. MATERIALES'!N28/'S. MATERIALES'!N27-1 -> 0.036057692 | T28: ='S. MATERIALES'!P28/'S. MATERIALES'!P27-1 -> 0.03125 | U28: ='S. MATERIALES'!R28/'S. MATERIALES'!R27-1 -> 0.056074766 | V28: ='S. MATERIALES'!T28/'S. MATERIALES'!T27-1 -> 0.062857143 | W28: =SUMPRODUCT(M28:V28,'Ponderaciones e Índices.'!$A$8:$J$8) -> 0.044896775 | X28: ='S. ENERGÍA'!B28/'S. ENERGÍA'!B27-1 -> 0.039791438 | Y28: ='S. ENERGÍA'!D28/'S. ENERGÍA'!D27-1 -> 0.051468074 | Z28: ='S. ENERGÍA'!F28/'S. ENERGÍA'!F27-1 -> -0.00048717116 | AA28: ='S. ENERGÍA'!H28/'S. ENERGÍA'!H27-1 -> 0.010004608 | AB28: ='S. ENERGÍA'!J28/'S. ENERGÍA'!J27-1 -> 0.058901099 | AC28: ='S. ENERGÍA'!L28/'S. ENERGÍA'!L27-1 -> 0.024951182 | AD28: ='S. ENERGÍA'!N28/'S. ENERGÍA'!N27-1 -> 0.01778809 | AE28: ='S. ENERGÍA'!P28/'S. ENERGÍA'!P27-1 -> 0.031286895 | AF28: ='S. ENERGÍA'!R28/'S. ENERGÍA'!R27-1 -> 0.059777968 | AG28: ='S. ENERGÍA'!T28/'S. ENERGÍA'!T27-1 -> 0.047835991 | AH28: =SUMPRODUCT(X28:AG28,'Ponderaciones e Índices.'!$A$12:$J$12) -> 0.042469869
A29: =S.FINANCIERO!A30 -> 42037 | B29: =S.FINANCIERO!B30/S.FINANCIERO!B28-1 -> 0.016308893 | C29: =S.FINANCIERO!D30/S.FINANCIERO!D28-1 -> 0.014229249 | D29: =S.FINANCIERO!F30/S.FINANCIERO!F28-1 -> 0.016164384 | E29: =S.FINANCIERO!H30/S.FINANCIERO!H28-1 -> 0.01621356 | F29: =S.FINANCIERO!J30/S.FINANCIERO!J28-1 -> 0.013268315 | G29: =S.FINANCIERO!L30/S.FINANCIERO!L28-1 -> 0.018321647 | H29: =S.FINANCIERO!N30/S.FINANCIERO!N28-1 -> 0.010966967 | I29: =S.FINANCIERO!P30/S.FINANCIERO!P28-1 -> 0.011346818 | J29: =S.FINANCIERO!R30/S.FINANCIERO!R28-1 -> 0.038857437 | K29: =S.FINANCIERO!T30/S.FINANCIERO!T28-1 -> 0.012108041 | L29: =SUMPRODUCT(B29:K29, 'Ponderaciones e Índices.'!$A$4:$J$4) -> 0.015445583 | M29: ='S. MATERIALES'!B30/'S. MATERIALES'!B28-1 -> -0.0024615385 | N29: ='S. MATERIALES'!D30/'S. MATERIALES'!D28-1 -> 0.014939309 | O29: ='S. MATERIALES'!F30/'S. MATERIALES'!F28-1 -> 0.01744645 | P29: ='S. MATERIALES'!H30/'S. MATERIALES'!H28-1 -> -0.0030832477 | Q29: ='S. MATERIALES'!J30/'S. MATERIALES'!J28-1 -> -0.0039547252 | R29: ='S. MATERIALES'!L30/'S. MATERIALES'!L28-1 -> 0.039513678 | S29: ='S. MATERIALES'!N30/'S. MATERIALES'!N28-1 -> -0.0069605568 | T29: ='S. MATERIALES'!P30/'S. MATERIALES'!P28-1 -> 0.063203463 | U29: ='S. MATERIALES'!R30/'S. MATERIALES'!R28-1 -> 0.037610619 | V29: ='S. MATERIALES'!T30/'S. MATERIALES'!T28-1 -> -0.001344086 | W29: =SUMPRODUCT(M29:V29,'Ponderaciones e Índices.'!$A$8:$J$8) -> 0.021528935 | X29: ='S. ENERGÍA'!B30/'S. ENERGÍA'!B28-1 -> 0.038532594 | Y29: ='S. ENERGÍA'!D30/'S. ENERGÍA'!D28-1 -> 0.060918685 | Z29: ='S. ENERGÍA'!F30/'S. ENERGÍA'!F28-1 -> 0.016571893 | AA29: ='S. ENERGÍA'!H30/'S. ENERGÍA'!H28-1 -> 0.015564965 | AB29: ='S. ENERGÍA'!J30/'S. ENERGÍA'!J28-1 -> 0.041511 | AC29: ='S. ENERGÍA'!L30/'S. ENERGÍA'!L28-1 -> 0.044665538 | AD29: ='S. ENERGÍA'!N30/'S. ENERGÍA'!N28-1 -> 0.029888551 | AE29: ='S. ENERGÍA'!P30/'S. ENERGÍA'!P28-1 -> 0.030623927 | AF29: ='S. ENERGÍA'!R30/'S. ENERGÍA'!R28-1 -> 0.042707494 | AG29: ='S. ENERGÍA'!T30/'S. ENERGÍA'!T28-1 -> 0.040434783 | AH29: =SUMPRODUCT(X29:AG29,'Ponderaciones e Índices.'!$A$12:$J$12) -> 0.043822238
